<?xml version="1.0" ?>
<!-- =================================================================================== -->
<!-- |    This document was autogenerated by xacro from /home/leo/ros2_ws/src/2024_capstone/leo_gazebo_simulation/urdf/cart.urdf.xacro | -->
<!-- |    EDITING THIS FILE BY HAND IS NOT RECOMMENDED                                 | -->
<!-- =================================================================================== -->
<robot name="sr1_trailer">
  <!-- This file is a placeholder which is included by default from
       ridgeback.urdf.xacro. If a robot is being customized and requires
       additional URDF, set the RIDGEBACK_URDF_EXTRAS environment variable
       to the full path of the file you would like included. -->
  <joint name="tow_hitch_joint" type="fixed">
    <origin rpy="0 0 0" xyz="-0.319 0 0.230"/>
    <parent link="top_link"/>
    <child link="tow_hitch_link"/>
  </joint>
  <link name="tow_hitch_link">
    <visual>
      <origin rpy="0 0 0" xyz="0 0 0.0125"/>
      <geometry>
        <cylinder length="0.025" radius="0.05"/>
      </geometry>
      <material name="yellow"/>
    </visual>
    <collision>
      <origin xyz="0 0 0.0125"/>
      <geometry>
        <cylinder length="0.025" radius="0.05"/>
      </geometry>
    </collision>
    <inertial>
      <origin rpy="0 0 0" xyz="0 0 0"/>
      <mass value="0.5"/>
      <inertia ixx="0.00033854166666666673" ixy="0" ixz="0" iyy="0.00033854166666666673" iyz="0" izz="0.0006250000000000001"/>
    </inertial>
  </link>
  <joint name="cargo_cart_joint" type="revolute">
    <origin rpy="0 0 0" xyz="0 0 0.025"/>
    <parent link="tow_hitch_link"/>
    <child link="cargo_cart_link"/>
    <axis xyz="0 0 1"/>
    <limit effort="0" lower="-2.199114857512855" upper="2.199114857512855" velocity="0"/>
    <dynamics damping="0.7" friction="0.5"/>
  </joint>
  <link name="cargo_cart_link">
    <visual>
      <origin rpy="0 0 0" xyz="-0.2 0 0.0125"/>
      <geometry>
        <box size="0.5 0.643 0.025"/>
        <material name="black"/>
      </geometry>
    </visual>
    <collision>
      <origin xyz="-0.2 0 0.0125"/>
      <geometry>
        <box size="0.5 0.643 0.025"/>
      </geometry>
    </collision>
    <inertial>
      <origin rpy="0 0 0" xyz="0 0 0"/>
      <mass value="2"/>
      <inertia ixx="0.06901233333333333" ixy="0" ixz="0" iyy="0.041770833333333326" iyz="0" izz="0.11057483333333332"/>
    </inertial>
  </link>
  <joint name="cargo_cart_mid_joint" type="fixed">
    <origin rpy="0 0 0" xyz="-0.4625 0 0.0125"/>
    <parent link="cargo_cart_link"/>
    <child link="cargo_cart_mid_link"/>
  </joint>
  <link name="cargo_cart_mid_link">
    <visual>
      <origin rpy="0 0 0" xyz="0 0 -0.0725"/>
      <geometry>
        <box size="0.025 0.643 0.17"/>
      </geometry>
    </visual>
    <collision>
      <origin xyz="0 0 -0.0725"/>
      <geometry>
        <box size="0.025 0.643 0.17"/>
      </geometry>
    </collision>
    <inertial>
      <origin rpy="0 0 0" xyz="0 0 0"/>
      <mass value="2"/>
      <inertia ixx="0.06901233333333333" ixy="0" ixz="0" iyy="0.004920833333333334" iyz="0" izz="0.07372483333333332"/>
    </inertial>
  </link>
  <joint name="cargo_cart_bed_joint" type="fixed">
    <origin rpy="0 0 0" xyz="0 0 -0.145"/>
    <parent link="cargo_cart_mid_link"/>
    <child link="cargo_cart_bed_link"/>
  </joint>
  <link name="cargo_cart_bed_link">
    <visual>
      <origin rpy="0 0 0" xyz="-0.2625 0 0"/>
      <geometry>
        <box size="0.5 0.643 0.025"/>
      </geometry>
    </visual>
    <collision>
      <origin xyz="-0.2625 0 0"/>
      <geometry>
        <box size="0.5 0.643 0.025"/>
      </geometry>
    </collision>
    <inertial>
      <origin rpy="0 0 0" xyz="0 0 0"/>
      <mass value="2"/>
      <inertia ixx="0.06901233333333333" ixy="0" ixz="0" iyy="0.041770833333333326" iyz="0" izz="0.11057483333333332"/>
    </inertial>
  </link>
  <!-- <joint name="dead_weight_joint" type="fixed">
      <origin xyz="0 0 0.0125" rpy="0 0 0" />
      <parent link="cargo_cart_bed_link"/>
      <child link="dead_weight_link" />
    </joint>

    <link name="dead_weight_link">
      <visual>
        <origin xyz="-0.25 0 0.125" rpy="0 0 0" />
        <geometry>
          <box size="0.25 0.25 0.25"/>
        </geometry>
      </visual>
      <collision>
        <origin xyz="-0.25 0 0.125"/>
        <geometry>
          <box size="0.25 0.25 0.25"/>
        </geometry>
      </collision>
      <inertial>
        <origin xyz="0 0 0" rpy="0 0 0"/>
        <mass value="${dead_weight}"/>
        <inertia
          ixx="${(((1/12)*dead_weight)*((0.25*0.25) + (0.25*0.25)))}" ixy="0" ixz="0"
          iyy="${(((1/12)*dead_weight)*((0.25*0.25) + (0.25*0.25)))}" iyz="0"
          izz="${(((1/12)*dead_weight)*((0.25*0.25) + (0.25*0.25)))}"/>
      </inertial>
    </link> -->
  <!-- <xacro:wheel_holder prefix="front" side="left" joint_type="fixed" location="0" s_location="1"> -->
  <!-- </xacro:wheel_holder> -->
  <!-- <xacro:wheel_holder prefix="front" side="right" joint_type="fixed" location="0" s_location="-1"> -->
  <!-- </xacro:wheel_holder> -->
  <joint name="rear_left_wheel_holder_joint" type="fixed">
    <parent link="cargo_cart_bed_link"/>
    <child link="rear_left_wheel_holder_link"/>
    <origin rpy="0 0 0" xyz="-0.4 0.28 -0.0125"/>
    <axis xyz="0 0 1"/>
    <!-- <limit lower="-${M_PI}" upper="${M_PI}" velocity="0" effort="0"/> -->
    <!-- <dynamics damping="${damping_coef}" friction="${friction_coef}" /> -->
  </joint>
  <!-- <transmission name="${prefix}_${side}_wheel_holder_trans">
        <type>transmission_interface/SimpleTransmission</type>
        <joint name="${prefix}_${side}_wheel_holder_joint">
          <!--<hardwareInterface>hardware_interface/VelocityJointInterface</hardwareInterface>-->
        </joint>
        <actuator name="${prefix}_${side}_wheel_holder_actuator">
          <mechanicalReduction>1</mechanicalReduction>
        </actuator>
      </transmission> -->
  <link name="rear_left_wheel_holder_link">
    <visual>
      <origin rpy="0 0 0" xyz="0 0 -0.005"/>
      <geometry>
        <box size="0.05 0.0790 0.01"/>
      </geometry>
    </visual>
    <collision>
      <origin rpy="0 0 0" xyz="0 0 -0.005"/>
      <geometry>
        <box size="0.05 0.0790 0.01"/>
      </geometry>
    </collision>
    <inertial>
      <origin rpy="0 0 0" xyz="0 0 0"/>
      <mass value="0.1"/>
      <inertia ixx="5.2841666666666666e-05" ixy="0" ixz="0" iyy="2.166666666666667e-05" iyz="0" izz="7.284166666666667e-05"/>
    </inertial>
  </link>
  <joint name="rear_left_wheel_holder_mid_joint" type="fixed">
    <parent link="rear_left_wheel_holder_link"/>
    <child link="rear_left_wheel_holder_mid_link"/>
    <origin rpy="0 0 0" xyz="0 0.0395 0"/>
  </joint>
  <link name="rear_left_wheel_holder_mid_link">
    <visual>
      <origin rpy="0 0 0" xyz="0 0.005 -0.055"/>
      <geometry>
        <box size="0.05 0.01 0.11"/>
      </geometry>
    </visual>
    <collision>
      <origin rpy="0 0 0" xyz="0 0.005 -0.055"/>
      <geometry>
        <box size="0.05 0.01 0.11"/>
      </geometry>
    </collision>
    <inertial>
      <origin rpy="0 0 0" xyz="0 0 0"/>
      <mass value="0.1"/>
      <inertia ixx="0.00010166666666666665" ixy="0" ixz="0" iyy="2.166666666666667e-05" iyz="0" izz="0.00012166666666666667"/>
    </inertial>
  </link>
  <joint name="rear_left_cart_wheel_joint" type="continuous">
    <parent link="rear_left_wheel_holder_mid_link"/>
    <child link="rear_left_cart_wheel_link"/>
    <axis xyz="0 1 0"/>
    <origin rpy="0 0 0" xyz="0 -0.0395 -0.11"/>
    <limit effort="0" lower="-31415.926535897932" upper="31415.926535897932" velocity="0"/>
  </joint>
  <transmission name="${prefix}_left_cart_wheel_trans">
    <type>transmission_interface/SimpleTransmission</type>
    <joint name="rear_left_cart_wheel_joint">
      <!--<hardwareInterface>hardware_interface/VelocityJointInterface</hardwareInterface>-->
    </joint>
    <actuator name="rear_left_cart_wheel_actuator">
      <mechanicalReduction>1</mechanicalReduction>
    </actuator>
  </transmission>
  <link name="rear_left_cart_wheel_link">
    <visual>
      <origin rpy="1.5707963267948966 0 0" xyz="0 0 0"/>
      <geometry>
        <mesh filename="package://sp_gazebo/meshes/trailer_wheel.stl"/>
      </geometry>
      <material name="black"/>
    </visual>
    <collision>
      <origin rpy="1.5707963267948966 0 0" xyz="0 0 0.000005"/>
      <geometry>
        <cylinder length="0.079" radius="0.0759"/>
      </geometry>
    </collision>
    <inertial>
      <origin rpy="0 0 0" xyz="0 0 0"/>
      <mass value="0.5"/>
      <inertia ixx="0.0009801429166666664" ixy="0" ixz="0" iyy="0.0009801429166666664" iyz="0" izz="0.0014402024999999998"/>
    </inertial>
  </link>
  <joint name="rear_right_wheel_holder_joint" type="fixed">
    <parent link="cargo_cart_bed_link"/>
    <child link="rear_right_wheel_holder_link"/>
    <origin rpy="0 0 0" xyz="-0.4 -0.28 -0.0125"/>
    <axis xyz="0 0 1"/>
    <!-- <limit lower="-${M_PI}" upper="${M_PI}" velocity="0" effort="0"/> -->
    <!-- <dynamics damping="${damping_coef}" friction="${friction_coef}" /> -->
  </joint>
  <!-- <transmission name="${prefix}_${side}_wheel_holder_trans">
        <type>transmission_interface/SimpleTransmission</type>
        <joint name="${prefix}_${side}_wheel_holder_joint">
          <!--<hardwareInterface>hardware_interface/VelocityJointInterface</hardwareInterface>-->
        </joint>
        <actuator name="${prefix}_${side}_wheel_holder_actuator">
          <mechanicalReduction>1</mechanicalReduction>
        </actuator>
      </transmission> -->
  <link name="rear_right_wheel_holder_link">
    <visual>
      <origin rpy="0 0 0" xyz="0 0 -0.005"/>
      <geometry>
        <box size="0.05 0.0790 0.01"/>
      </geometry>
    </visual>
    <collision>
      <origin rpy="0 0 0" xyz="0 0 -0.005"/>
      <geometry>
        <box size="0.05 0.0790 0.01"/>
      </geometry>
    </collision>
    <inertial>
      <origin rpy="0 0 0" xyz="0 0 0"/>
      <mass value="0.1"/>
      <inertia ixx="5.2841666666666666e-05" ixy="0" ixz="0" iyy="2.166666666666667e-05" iyz="0" izz="7.284166666666667e-05"/>
    </inertial>
  </link>
  <joint name="rear_right_wheel_holder_mid_joint" type="fixed">
    <parent link="rear_right_wheel_holder_link"/>
    <child link="rear_right_wheel_holder_mid_link"/>
    <origin rpy="0 0 0" xyz="0 -0.0395 0"/>
  </joint>
  <link name="rear_right_wheel_holder_mid_link">
    <visual>
      <origin rpy="0 0 0" xyz="0 -0.005 -0.055"/>
      <geometry>
        <box size="0.05 0.01 0.11"/>
      </geometry>
    </visual>
    <collision>
      <origin rpy="0 0 0" xyz="0 -0.005 -0.055"/>
      <geometry>
        <box size="0.05 0.01 0.11"/>
      </geometry>
    </collision>
    <inertial>
      <origin rpy="0 0 0" xyz="0 0 0"/>
      <mass value="0.1"/>
      <inertia ixx="0.00010166666666666665" ixy="0" ixz="0" iyy="2.166666666666667e-05" iyz="0" izz="0.00012166666666666667"/>
    </inertial>
  </link>
  <joint name="rear_right_cart_wheel_joint" type="continuous">
    <parent link="rear_right_wheel_holder_mid_link"/>
    <child link="rear_right_cart_wheel_link"/>
    <axis xyz="0 1 0"/>
    <origin rpy="0 0 0" xyz="0 0.0395 -0.11"/>
    <limit effort="0" lower="-31415.926535897932" upper="31415.926535897932" velocity="0"/>
  </joint>
  <transmission name="${prefix}_right_cart_wheel_trans">
    <type>transmission_interface/SimpleTransmission</type>
    <joint name="rear_right_cart_wheel_joint">
      <!--<hardwareInterface>hardware_interface/VelocityJointInterface</hardwareInterface>-->
    </joint>
    <actuator name="rear_right_cart_wheel_actuator">
      <mechanicalReduction>1</mechanicalReduction>
    </actuator>
  </transmission>
  <link name="rear_right_cart_wheel_link">
    <visual>
      <origin rpy="1.5707963267948966 0 0" xyz="0 0 0"/>
      <geometry>
        <mesh filename="package://sp_gazebo/meshes/trailer_wheel.stl"/>
      </geometry>
      <material name="black"/>
    </visual>
    <collision>
      <origin rpy="1.5707963267948966 0 0" xyz="0 0 0.000005"/>
      <geometry>
        <cylinder length="0.079" radius="0.0759"/>
      </geometry>
    </collision>
    <inertial>
      <origin rpy="0 0 0" xyz="0 0 0"/>
      <mass value="0.5"/>
      <inertia ixx="0.0009801429166666664" ixy="0" ixz="0" iyy="0.0009801429166666664" iyz="0" izz="0.0014402024999999998"/>
    </inertial>
  </link>
</robot>
