<?xml version="1.0" ?>
<!-- =================================================================================== -->

<robot name="tractor">
  <link name="robot_footprint"/>
  <gazebo>
    <plugin filename="libgazebo_ros_diff_drive.so" name="diff_drive">
      <ros>
        <namespace></namespace>
        <!--<remapping>cmd_vel:=cmd_vel</remapping>-->
        <!--<remapping>odom:=odom</remapping>-->
      </ros>
      <!-- wheels -->
      <left_joint>left_wheel_hinge</left_joint>
      <right_joint>right_wheel_hinge</right_joint>
      <!-- kinematics -->
      <wheel_separation>0.507</wheel_separation>
      <wheel_diameter>0.1</wheel_diameter>
      <!-- limits -->
      <max_wheel_torque>10</max_wheel_torque>
      <max_wheel_acceleration>1.0</max_wheel_acceleration>
      <!-- output -->
      <publish_odom>true</publish_odom>
      <publish_odom_tf>true</publish_odom_tf>
      <publish_wheel_tf>true</publish_wheel_tf>
      <odometry_frame>odom</odometry_frame>
      <robot_base_frame>robot_footprint</robot_base_frame>
    </plugin>
  </gazebo>
  <!-- camera -->
  <gazebo reference="camera">
    <sensor name="camera_sensor" type="camera">
      <update_rate>30.0</update_rate>
      <always_on>1</always_on>
      <camera name="camera">
        <horizontal_fov>1.3962634</horizontal_fov>
        <image>
          <width>800</width>
          <height>800</height>
          <format>R8G8B8</format>
        </image>
        <clip>
          <near>0.02</near>
          <far>300</far>
        </clip>
        <distortion>
          <k1>0.0</k1>
          <k2>0.0</k2>
          <k3>0.0</k3>
          <p1>0.0</p1>
          <p2>0.0</p2>
          <center>0.5 0.5</center>
        </distortion>
      </camera>
      <plugin filename="libgazebo_ros_camera.so" name="camera_controller">
        <ros>
          <namespace>/tractor</namespace>
          <argument>camera/image_raw:=/tractor/camera/image</argument>
          <argument>camera/camera_info:=/tractor/camera/image/camera_info</argument>
        </ros>
        <camera_name>camera_sensor</camera_name>
        <frame_name>base_link</frame_name>
        <hack_baseline>0.07</hack_baseline>
      </plugin>
    </sensor>
  </gazebo>
  <!-- hokuyo -->
  <gazebo reference="hokuyo">
    <sensor name="head_hokuyo_sensor" type="ray">
      <pose>0 0 0 0 0 0</pose>
      <visualize>false</visualize>
      <update_rate>40</update_rate>
      <ray>
        <scan>
          <horizontal>
            <samples>720</samples>
            <resolution>1</resolution>
            <min_angle>-1.570796</min_angle>
            <max_angle>1.570796</max_angle>
          </horizontal>
        </scan>
        <range>
          <min>0.10</min>
          <max>30.0</max>
          <resolution>0.01</resolution>
        </range>
        <noise>
          <type>gaussian</type>
          <!-- Noise parameters based on published spec for Hokuyo laser
                achieving "+-30mm" accuracy at range < 10m.  A mean of 0.0m and
                stddev of 0.01m will put 99.7% of samples within 0.03m of the true
                reading. -->
          <mean>0.0</mean>
          <stddev>0.01</stddev>
        </noise>
      </ray>
      <update_rate>30</update_rate>
      <plugin filename="libgazebo_ros_ray_sensor.so" name="gazebo_ros_head_hokuyo_controller">
        <ros>
          <namespace></namespace>
          <argument>~/out:=scan</argument>
        </ros>
        <output_type>sensor_msgs/LaserScan</output_type>
      </plugin>
    </sensor>
  </gazebo>
  <joint name="robot_footprint_joint" type="fixed">
    <origin rpy="0 0 0" xyz="0 0 0"/>
    <parent link="robot_footprint"/>
    <child link="base_link"/>
  </joint>
  <link name="base_link">
    <pose>0 0 0.1 0 0 0</pose>
    <inertial>
      <mass value="15.0"/>
      <origin rpy=" 0 0 0" xyz="0.0 0 0"/>
      <inertia ixx="0.1" ixy="0" ixz="0" iyy="0.1" iyz="0" izz="0.1"/>
    </inertial>
    <collision name="collision">
      <origin rpy=" 0 0 0" xyz="0 0 0"/>
      <geometry>
        <box size=".65 .4 .2"/>
      </geometry>
    </collision>
    <visual name="base_link_visual">
      <origin rpy=" 0 0 0" xyz="0 0 0"/>
      <geometry>
        <box size=".65 .4 .2"/>
      </geometry>
    </visual>
    <collision name="back_caster_collision">
      <origin rpy=" 0 0 0" xyz="-0.3 0 -0.15"/>
      <geometry>
        <sphere radius="0.0499"/>
      </geometry>
    </collision>
    <visual name="back_caster_visual">
      <origin rpy=" 0 0 0" xyz="-0.3 0 -0.15"/>
      <geometry>
        <sphere radius="0.05"/>
      </geometry>
    </visual>
    <collision name="front_caster_collision">
      <origin rpy=" 0 0 0" xyz="0.3 0 -0.15"/>
      <geometry>
        <sphere radius="0.0499"/>
      </geometry>
    </collision>
    <visual name="front_caster_visual">
      <origin rpy=" 0 0 0" xyz="0.3 0 -0.15"/>
      <geometry>
        <sphere radius="0.05"/>
      </geometry>
    </visual>
  </link>
  <link name="left_wheel">
    <inertial>
      <mass value="5.0"/>
      <origin rpy=" 0 1.5707 1.5707" xyz="0.0 0 0"/>
      <inertia ixx="0.1" ixy="0" ixz="0" iyy="0.1" iyz="0" izz="0.1"/>
    </inertial>
    <collision>
      <origin rpy=" 0 1.5707 1.5707" xyz="0 0 0"/>
      <geometry>
        <cylinder length="0.06" radius="0.2"/>
      </geometry>
    </collision>
    <visual>
      <origin rpy=" 0 1.5707 1.5707" xyz="0 0 0"/>
      <geometry>
        <cylinder length="0.06" radius="0.2"/>
      </geometry>
    </visual>
  </link>
  <link name="right_wheel">
    <inertial>
      <mass value="5.0"/>
      <origin rpy=" 0 1.5707 1.5707" xyz="0.0 0 0"/>
      <inertia ixx="0.1" ixy="0" ixz="0" iyy="0.1" iyz="0" izz="0.1"/>
    </inertial>
    <collision name="collision">
      <origin rpy=" 0 1.5707 1.5707" xyz="0 0 0"/>
      <geometry>
        <cylinder length="0.06" radius="0.2"/>
      </geometry>
    </collision>
    <visual name="right_wheel_visual">
      <origin rpy=" 0 1.5707 1.5707" xyz="0 0 0"/>
      <geometry>
        <cylinder length="0.06" radius="0.2"/>
      </geometry>
    </visual>
  </link>
  <joint name="left_wheel_hinge" type="continuous">
    <origin rpy="0 0 0" xyz="0 0.23 0"/>
    <child link="left_wheel"/>
    <parent link="base_link"/>
    <axis rpy="0 0 0" xyz="0 1 0"/>
    <limit effort="10000" velocity="1000"/>
    <dynamics damping="1.0" friction="1.0"/>
  </joint>
  
  <joint name="right_wheel_hinge" type="continuous">
    <origin rpy="0 0 0" xyz="0 -0.23 0"/>
    <child link="right_wheel"/>
    <parent link="base_link"/>
    <axis rpy="0 0 0" xyz="0 1 0"/>
    <limit effort="10000" velocity="1000"/>
    <dynamics damping="1.0" friction="1.0"/>
  </joint>
  
  <link name="camera">
    <pose>0 0 0 0 0 0</pose>
    <inertial>
      <mass value="0.1"/>
      <origin rpy="0.0 0 0" xyz="0.0 0 0"/>
      <inertia ixx="1e-6" ixy="0" ixz="0" iyy="1e-6" iyz="0" izz="1e-6"/>
    </inertial>
    <collision name="collision">
      <origin rpy=" 0 0 0" xyz="0 0 0"/>
      <geometry>
        <box size="0.05 0.1 0.05"/>
      </geometry>
    </collision>
    <visual name="camera_visual">
      <origin rpy="0 0 0" xyz="0 0 0"/>
      <geometry>
        <box size="0.05 0.1 0.05"/>
      </geometry>
    </visual>
  </link>
  <joint name="camera_joint" type="fixed">
    <origin rpy="0 0 0" xyz="0.3 0 0.18"/>
    <child link="camera"/>
    <parent link="base_link"/>
    <axis rpy="0 0 0" xyz="0 1 0"/>
    <limit effort="10000" velocity="1000"/>
    <dynamics damping="1.0" friction="1.0"/>
  </joint>
  <link name="hokuyo">
    <inertial>
      <mass value="1e-5"/>
      <origin rpy="0.0 0 0" xyz="0.0 0 0"/>
      <inertia ixx="1e-6" ixy="0" ixz="0" iyy="1e-6" iyz="0" izz="1e-6"/>
    </inertial>
    <collision name="collision">
      <origin rpy=" 0 0 0" xyz="0 0 0"/>
      <geometry>
        <cylinder radius="0.025" length="0.05"/>
      </geometry>
    </collision>
    <visual name="hokuyo_visual">
      <origin rpy="0 0 0" xyz="0 0 0"/>
      <geometry>
        <cylinder radius="0.03" length="0.05"/>
      </geometry>
    </visual>
  </link>
  <joint name="hokuyo_joint" type="fixed">
    <origin rpy="0 0 0" xyz="0.3 0.0 0.13"/>
    <child link="hokuyo"/>
    <parent link="base_link"/>
    <axis rpy="0 0 0" xyz="0 1 0"/>
    <limit effort="10000" velocity="1000"/>
    <dynamics damping="1.0" friction="1.0"/>
  </joint>
  
  <!--IMU-->
  <link name="imu_link">
  <inertial>
    <mass value="0.001"/>
    <inertia ixx="0.1" ixy="0" ixz="0" iyy="0.1" iyz="0" izz="0.1"/>
  </inertial>
 </link>
 <joint name="imu_joint" type="fixed">
    <parent link="base_link" />
    <child link="imu_link" />
    <!--<origin xyz="${imu_offset_x} ${imu_offset_y} ${imu_offset_z}" rpy="0 0 0"/>-->
    <origin xyz="0 0 .2" rpy="0 0 0" />
  </joint>
 <gazebo reference="imu_link">
  <sensor type="imu" name="imu_sensor">
    <always_on>true</always_on>
    <update_rate>50.0</update_rate>
    <plugin name="imu_controller" filename="libgazebo_ros_imu_sensor.so">
      <ros>
        <namespace>/</namespace>
      </ros>
      <alwaysOn>true</alwaysOn>
      <bodyName>imu_link</bodyName>
      <topicName>imu_data</topicName>
      <updateRate>50.0</updateRate>
      <frameId>imu_link</frameId>
      <gaussianNoise>0.0</gaussianNoise>
      <xyzOffsets>0 0 0</xyzOffsets>
      <rpyOffsets>0 0 0</rpyOffsets>
      <sensorBaseFrame>imu_link</sensorBaseFrame>
    </plugin>
  </sensor>
</gazebo>

  
  <gazebo reference="left_wheel">
    <material>Gazebo/Yellow</material>
  </gazebo>
  <gazebo reference="right_wheel">
    <material>Gazebo/Yellow</material>
  </gazebo>
  <gazebo reference="base_link">
    <material>Gazebo/Gray</material>
  </gazebo>
  <gazebo reference="camera">
    <material>Gazebo/Blue</material>
  </gazebo>
  <gazebo reference="hokuyo">
    <material>Gazebo/Red</material>
  </gazebo>
</robot>
