<?xml version="1.0" ?>
<!-- =================================================================================== -->

<robot name="trailer">
  <link name="robot_footprint"/>
  
  <joint name="base_link_joint" type="fixed">
    <origin rpy="0 0 0" xyz="0 0 1"/>
    <parent link="robot_footprint"/>
    <child link="base_link"/>
  </joint>
  <link name="base_link">
    <pose>0 0 0 0 0 0</pose>
    <inertial>
      <mass value="15.0"/>
      <origin rpy=" 0 0 0" xyz="0.0 0 0"/>
      <inertia ixx="0.1" ixy="0" ixz="0" iyy="0.1" iyz="0" izz="0.1"/>
    </inertial>
    <collision name="collision">
      <origin rpy=" 0 0 0" xyz="0 0 0"/>
      <geometry>
        <box size="2 1 2"/>
      </geometry>
    </collision>
    <visual name="base_link_visual">
      <origin rpy=" 0 0 0" xyz="0 0 0"/>
      <geometry>
        <box size="2 1 2"/>
      </geometry>
    </visual>
  </link>
  <link name="front_left_wheel">
    <inertial>
      <mass value="3.0"/>
      <origin rpy=" 0 1.5707 1.5707" xyz="0.0 0 0"/>
      <inertia ixx="0.1" ixy="0" ixz="0" iyy="0.1" iyz="0" izz="0.1"/>
    </inertial>
    <collision>
      <origin rpy=" 0 1.5707 1.5707" xyz="0 0 0"/>
      <geometry>
        <cylinder length="0.06" radius="0.1"/>
      </geometry>
    </collision>
    <visual>
      <origin rpy=" 0 1.5707 1.5707" xyz="0 0 0"/>
      <geometry>
        <cylinder length="0.06" radius="0.1"/>
      </geometry>
    </visual>
  </link>
  <link name="front_right_wheel">
    <inertial>
      <mass value="3.0"/>
      <origin rpy=" 0 1.5707 1.5707" xyz="0 0 0"/>
      <inertia ixx="0.1" ixy="0" ixz="0" iyy="0.1" iyz="0" izz="0.1"/>
    </inertial>
    <collision name="collision">
      <origin rpy=" 0 1.5707 1.5707" xyz="0 0 0"/>
      <geometry>
        <cylinder length="0.06" radius="0.1"/>
      </geometry>
    </collision>
    <visual>
      <origin rpy=" 0 1.5707 1.5707" xyz="0 0 0"/>
      <geometry>
        <cylinder length="0.06" radius="0.1"/>
      </geometry>
    </visual>
  </link>
  <joint name="front_left_wheel" type="continuous">
    <origin rpy="0 0 0" xyz="1 .5 0"/>
    <child link="front_left_wheel"/>
    <parent link="robot_footprint"/>
    <axis rpy="0 0 0" xyz="0 1 0"/>
    <limit effort="10000" velocity="1000"/>
    <dynamics damping="1.0" friction="0.6"/>
  </joint>
  
  <joint name="front_right_wheel" type="continuous">
    <origin rpy="0 0 0" xyz="-1 .5 0"/>
    <child link="front_right_wheel"/>
    <parent link="robot_footprint"/>
    <axis rpy="0 0 0" xyz="0 1 0"/>
    <limit effort="10000" velocity="1000"/>
    <dynamics damping="1.0" friction="0.6"/>
  </joint>
  
  <link name="back_left_wheel">
    <inertial>
      <mass value="3.0"/>
      <origin rpy=" 0 1.5707 1.5707" xyz="0.0 0 0"/>
      <inertia ixx="0.1" ixy="0" ixz="0" iyy="0.1" iyz="0" izz="0.1"/>
    </inertial>
    <collision>
      <origin rpy=" 0 1.5707 1.5707" xyz="0 0 0"/>
      <geometry>
        <cylinder length="0.06" radius="0.1"/>
      </geometry>
    </collision>
    <visual>
      <origin rpy=" 0 1.5707 1.5707" xyz="0 0 0"/>
      <geometry>
        <cylinder length="0.06" radius="0.1"/>
      </geometry>
    </visual>
  </link>
  <link name="back_right_wheel">
    <inertial>
      <mass value="3.0"/>
      <origin rpy=" 0 1.5707 1.5707" xyz="0 0 0"/>
      <inertia ixx="0.1" ixy="0" ixz="0" iyy="0.1" iyz="0" izz="0.1"/>
    </inertial>
    <collision name="collision">
      <origin rpy=" 0 1.5707 1.5707" xyz="0 0 0"/>
      <geometry>
        <cylinder length="0.06" radius="0.1"/>
      </geometry>
    </collision>
    <visual>
      <origin rpy=" 0 1.5707 1.5707" xyz="0 0 0"/>
      <geometry>
        <cylinder length="0.06" radius="0.1"/>
      </geometry>
    </visual>
  </link>
  <joint name="back_left_wheel" type="continuous">
    <origin rpy="0 0 0" xyz="1.0 -.5 0"/>
    <child link="back_left_wheel"/>
    <parent link="robot_footprint"/>
    <axis rpy="0 0 0" xyz="0 1 0"/>
    <limit effort="10000" velocity="1000"/>
    <dynamics damping="1.0" friction="0.6"/>
  </joint>
  
  <joint name="back_right_wheel" type="continuous">
    <origin rpy="0 0 0" xyz="-1 -.5 0"/>
    <child link="back_right_wheel"/>
    <parent link="robot_footprint"/>
    <axis rpy="0 0 0" xyz="0 1 0"/>
    <limit effort="10000" velocity="1000"/>
    <dynamics damping="1.0" friction="0.6"/>
  </joint>
  <link name="hook_link">
    <inertial>
      <mass value="1.0"/>
      <origin rpy=" 0 1.5707 1.5707" xyz="0 0 0"/>
      <inertia ixx="0.1" ixy="0" ixz="0" iyy="0.1" iyz="0" izz="0.1"/>
    </inertial>
    <collision name="collision">
      <origin rpy=" 0 1.5707 1.5707" xyz="0 0 0"/>
      <geometry>
        <box size="2 1 2"/>
      </geometry>
    </collision>
    <visual>
      <origin rpy=" 0 1.5707 1.5707" xyz="0 0 0"/>
      <geometry>
        <cylinder length="0.06" radius="0.1"/>
      </geometry>
    </visual>
  </link>
  
  <joint name="hook_joint" type="continuous">
    <origin rpy="0 0 0" xyz="-1 0 0"/>
    <child link="hook_link"/>
    <parent link="robot_footprint"/>
    <axis rpy="0 0 0" xyz="0 1 0"/>
    <limit effort="10000" velocity="1000"/>
  </joint>

</robot>
